Workbook

Sheet Overview
B1: Manufacturer | C1: ISO code | D1: Latitude | E1: Longitude | G1: Manufacturers_unique | H1: Frequency
C2: Code ISO 3166.1 | D2: WGS84 | E2: WGS84 | G2: #ND | H2: =COUNTIF($B$3:$B$27159,G2) -> 2782 | K2: Total | L2: =COUNTA(B3:B27159) -> 27157 | O2: =L2-L3 -> 24375
B3: #ND | C3: AL | D3: 41.798067 | E3: 19.640204 | G3: Enercon | H3: =COUNTIF($B$3:$B$27159,G3) -> 7299 | K3: #ND | L3: 2782 | M3: =L3/$L$2 -> 0.10244136
B4: #ND | C4: AL | D4: 41.798067 | E4: 19.640204 | G4: Vestas | H4: =COUNTIF($B$3:$B$27159,G4) -> 6131 | J4: 1 | K4: Enercon | L4: 7299 | M4: =L4/$L$2 -> 0.26877048 | O4: =L4/O2 -> 0.29944615
B5: #ND | C5: AL | D5: 41.091668 | E5: 19.52896 | G5: Repower | H5: =COUNTIF($B$3:$B$27159,G5) -> 466 | J5: 2 | K5: Vestas | L5: 6131 | M5: =L5/$L$2 -> 0.22576131 | O5: =L5/$O$2 -> 0.25152821
B6: #ND | C6: AT | D6: #ND | E6: #ND | G6: Dewind | H6: =COUNTIF($B$3:$B$27159,G6) -> 218 | J6: 3 | K6: Nordex | L6: 1725 | M6: =L6/$L$2 -> 0.063519535 | O6: =L6/$O$2 -> 0.070769231
B7: #ND | C7: AT | D7: #ND | E7: #ND | G7: Seewind | H7: =COUNTIF($B$3:$B$27159,G7) -> 24 | J7: 4 | K7: Neg Micon | L7: 1139 | M7: =L7/$L$2 -> 0.041941304 | O7: =L7/$O$2 -> 0.046728205
B8: Enercon | C8: AT | D8: 47.832268 | E8: 17.023676 | G8: Neg Micon | H8: =COUNTIF($B$3:$B$27159,G8) -> 1139 | J8: 5 | K8: Senvion | L8: 968 | M8: =L8/$L$2 -> 0.035644585 | O8: =L8/$O$2 -> 0.039712821
B9: Enercon | C9: AT | D9: 47.777965 | E9: 17.033402 | G9: GE Energy | H9: =COUNTIF($B$3:$B$27159,G9) -> 782 | J9: 6 | K9: Bonus | L9: 968 | M9: =L9/$L$2 -> 0.035644585 | O9: =L9/$O$2 -> 0.039712821
B10: Enercon | C10: AT | D10: 47.777965 | E10: 17.033402 | G10: Senvion | H10: =COUNTIF($B$3:$B$27159,G10) -> 968 | J10: 7 | K10: Gamesa | L10: 943 | M10: =L10/$L$2 -> 0.034724012 | O10: =L10/$O$2 -> 0.038687179
B11: Vestas | C11: AT | D11: 47.936175 | E11: 16.529969 | G11: Bonus | H11: =COUNTIF($B$3:$B$27159,G11) -> 968 | J11: 8 | K11: GE Energy | L11: 782 | M11: =L11/$L$2 -> 0.028795522 | O11: =L11/$O$2 -> 0.032082051
B12: Enercon | C12: AT | D12: 47.738071 | E12: 16.501303 | G12: Windtec | H12: =COUNTIF($B$3:$B$27159,G12) -> 1 | J12: 9 | K12: Siemens | L12: 499 | M12: =L12/$L$2 -> 0.018374636 | O12: =L12/$O$2 -> 0.020471795
B13: Vestas | C13: AT | D13: 48.011504 | E13: 16.828805 | G13: Nordex | H13: =COUNTIF($B$3:$B$27159,G13) -> 1725 | J13: 10 | K13: Repower | L13: 466 | M13: =L13/$L$2 -> 0.01715948 | N13: =SUM(M4:M13) -> 0.77033546 | O13: =L13/$O$2 -> 0.019117949
B14: Repower | C14: AT | D14: 47.579728 | E14: 16.620195 | G14: Micon | H14: =COUNTIF($B$3:$B$27159,G14) -> 385 | J14: 11 | K14: Micon | L14: 385 | M14: =L14/$L$2 -> 0.014176824 | O14: =L14/$O$2 -> 0.015794872
B15: Enercon | C15: AT | D15: 47.574785 | E15: 16.613541 | G15: Lagerwey | H15: =COUNTIF($B$3:$B$27159,G15) -> 47 | J15: 12 | K15: Nordtank | L15: 374 | M15: =L15/$L$2 -> 0.013771772 | O15: =L15/$O$2 -> 0.01534359
B16: Enercon | C16: AT | D16: 47.576417 | E16: 16.62128 | G16: Tacke | H16: =COUNTIF($B$3:$B$27159,G16) -> 264 | J16: 13 | K16: Wind World | L16: 325 | M16: =L16/$L$2 -> 0.011967449 | O16: =L16/$O$2 -> 0.013333333
B17: Enercon | C17: AT | D17: 48.038272 | E17: 17.000084 | G17: Leitwind | H17: =COUNTIF($B$3:$B$27159,G17) -> 32 | J17: 14 | K17: Tacke | L17: 264 | M17: =L17/$L$2 -> 0.0097212505 | O17: =L17/$O$2 -> 0.010830769
B18: #ND | C18: AT | D18: 48.015774 | E18: 16.963033 | G18: Siemens | H18: =COUNTIF($B$3:$B$27159,G18) -> 499 | J18: 15 | K18: Dewind | L18: 218 | M18: =L18/$L$2 -> 0.0080273963 | O18: =L18/$O$2 -> 0.0089435897
B19: Vestas | C19: AT | D19: 47.93 | E19: 16.94 | G19: Hewind | H19: =COUNTIF($B$3:$B$27159,G19) -> 2 | J19: 16 | K19: Siemens-Gamesa | L19: 184 | M19: =L19/$L$2 -> 0.006775417 | O19: =L19/$O$2 -> 0.0075487179
B20: Dewind | C20: AT | D20: 47.93 | E20: 16.94 | G20: Vensys | H20: =COUNTIF($B$3:$B$27159,G20) -> 90 | J20: 17 | K20: Fuhrländer | L20: 182 | M20: =L20/$L$2 -> 0.0067017712 | O20: =L20/$O$2 -> 0.0074666667
B21: Dewind | C21: AT | D21: 47.93 | E21: 16.94 | G21: Xant | H21: =COUNTIF($B$3:$B$27159,G21) -> 5 | J21: 18 | K21: Südwind | L21: 128 | M21: =L21/$L$2 -> 0.0047133336 | O21: =L21/$O$2 -> 0.0052512821
B22: Vestas | C22: AT | D22: 47.93 | E22: 16.94 | G22: Enron | H22: =COUNTIF($B$3:$B$27159,G22) -> 61 | J22: 19 | K22: Ecotecnia | L22: 128 | M22: =L22/$L$2 -> 0.0047133336 | O22: =L22/$O$2 -> 0.0052512821
B23: Vestas | C23: AT | D23: 47.93 | E23: 16.94 | G23: Turbowinds | H23: =COUNTIF($B$3:$B$27159,G23) -> 18 | J23: 20 | K23: Made | L23: 95 | M23: =L23/$L$2 -> 0.0034981773 | N23: =SUM(M4:M23) -> 0.85440218 | O23: =L23/$O$2 -> 0.0038974359
B24: Vestas | C24: AT | D24: 47.93 | E24: 16.94 | G24: Siemens-Gamesa | H24: =COUNTIF($B$3:$B$27159,G24) -> 184 | K24: Vensys | L24: 90
B25: Vestas | C25: AT | D25: 47.93 | E25: 16.94 | G25: Gamesa | H25: =COUNTIF($B$3:$B$27159,G25) -> 943 | K25: Acciona | L25: 87
B26: #ND | C26: AT | D26: 47.939296 | E26: 16.954532 | G26: Fuhrländer | H26: =COUNTIF($B$3:$B$27159,G26) -> 182 | K26: EWT | L26: 70
B27: Vestas | C27: AT | D27: 47.93 | E27: 16.94 | G27: Alstom Power | H27: =COUNTIF($B$3:$B$27159,G27) -> 17 | K27: e.n.o. energy | L27: 67
B28: Seewind | C28: AT | D28: 47.85549 | E28: 17.000508 | G28: MHI Vestas Offshore | H28: =COUNTIF($B$3:$B$27159,G28) -> 16 | K28: Winwind | L28: 66
B29: Enercon | C29: AT | D29: 47.842563 | E29: 17.002888 | G29: Goldwind | H29: =COUNTIF($B$3:$B$27159,G29) -> 4 | K29: Enron | L29: 61
B30: Enercon | C30: AT | D30: 47.845581 | E30: 17.000937 | G30: Mitsubishi | H30: =COUNTIF($B$3:$B$27159,G30) -> 5 | K30: Wincon | L30: 54
B31: Enercon | C31: AT | D31: 47.894822 | E31: 17.027656 | G31: Suzlon | H31: =COUNTIF($B$3:$B$27159,G31) -> 19 | K31: Danwin | L31: 50
B32: Enercon | C32: AT | D32: 47.851417 | E32: 17.009367 | G32: Guangdong Mingyang | H32: =COUNTIF($B$3:$B$27159,G32) -> 2 | K32: Lagerwey | L32: 47
B33: Enercon | C33: AT | D33: 48.070738 | E33: 17.055578 | G33: Shanghai Electric | H33: =COUNTIF($B$3:$B$27159,G33) -> 1 | K33: Leitwind | L33: 32
B34: Enercon | C34: AT | D34: 48.070738 | E34: 17.055578 | G34: Acciona | H34: =COUNTIF($B$3:$B$27159,G34) -> 87 | K34: Vergnet | L34: 32
B35: Vestas | C35: AT | D35: 48.082219 | E35: 17.012881 | G35: Koncar | H35: =COUNTIF($B$3:$B$27159,G35) -> 2 | K35: Vindsyssel | L35: 26
... B116: Nordex | C116: AT | D116: 48.148912 | E116: 16.811834 | G116: WindFlow | H116: =COUNTIF($B$3:$B$27159,G116) -> 2 | K116: Global Wind Power | L116: 1
B117: Enercon | C117: AT | D117: 48.339544 | E117: 16.51994 | K117: Samsung | L117: 1
B118: Enercon | C118: AT | D118: 47.967226 | E118: 14.660119
B119: Enercon | C119: AT | D119: 48.049846 | E119: 15.590744
B120: Micon | C120: AT | D120: 48.1852 | E120: 16.463928
...

Sheet Locations
A2: 1 | B2: Enercon | C2: 7299 | D2: =C2/Overview!$L$2 -> 0.26877048 | G2: Address_HQ | H2: sub-component production | J2: Address | K2: lon | L2: lat
A3: 2 | B3: Vestas | C3: 6131 | D3: =C3/Overview!$L$2 -> 0.22576131 | E3: =D3+D2 -> 0.4945318 | G3: ENERCON | H3: Generator | I3: DE | J3: August-Bebel-Damm 26, 39126 Magdeburg, Germany | K3: 11.68085 | L3: 52.20541
A4: 3 | B4: Nordex | C4: 1725 | D4: =C4/Overview!$L$2 -> 0.063519535 | H4: Generator | I4: PL | J4: Oświęcimska 102e, 45-641 Opole, Poland | K4: 17.95966 | L4: 50.60241
A5: 4 | B5: Neg Micon | C5: 1139 | D5: =C5/Overview!$L$2 -> 0.041941304 | H5: Generator | I5: PT | J5: Parque Empresarial de Lanheses, Lanheses, Portugal | K5: -8.6256 | L5: 41.9989
A6: 5 | B6: Senvion | C6: 968 | D6: =C6/Overview!$L$2 -> 0.035644585 | H6: Hub | I6: DE | J6: Borsigstraße 15, 26607 Aurich, Germany | K6: 7.49775 | L6: 53.50891
A7: 6 | B7: Bonus | C7: 968 | D7: =C7/Overview!$L$2 -> 0.035644585 | H7: Nacelle | I7: DE | J7: Borsigstraße 15, 26607 Aurich, Germany | K7: 7.49775 | L7: 53.50891
A8: 7 | B8: Gamesa | C8: 943 | D8: =C8/Overview!$L$2 -> 0.034724012 | H8: Blades | I8: PT | J8: Av. de Cabo Verde 36, Viana do Castelo, Portugal | K8: -8.84806 | L8: 41.6929
A9: 8 | B9: GE Energy | C9: 782 | D9: =C9/Overview!$L$2 -> 0.028795522 | H9: Blades | I9: TR | J9: 10042 Sokak No 12 İAOSB, 35680 Çiğli/İzmir, Türkiye | K9: 27.031804 | L9: 38.474006
A10: 9 | B10: Siemens | C10: 499 | D10: =C10/Overview!$L$2 -> 0.018374636 | G10: VESTAS | H10: Blades | I10: DK | J10: Vingevej 1, 4900 Nakskov, Denmark | K10: 11.12127 | L10: 54.828999
A11: 10 | B11: Repower | C11: 466 | D11: =C11/Overview!$L$2 -> 0.01715948 | E11: =SUM(D2:D11) -> 0.77033546 | H11: Blades | I11: DK | J11: Smed Hansensvej 19, 6940 Lem, Denmark | K11: 8.3829 | L11: 56.021679
A12: 11 | B12: Micon | C12: 385 | D12: =C12/Overview!$L$2 -> 0.014176824 | H12: Nacelles | I12: DK | J12: E.F. Jacobsensvej 3, 6950 Ringkobing, Denmark | K12: 8.23574 | L12: 56.08888
A13: 12 | B13: Nordtank | C13: 374 | D13: =C13/Overview!$L$2 -> 0.013771772 | H13: Nacelles | I13: DK | J13: Lindø Sydvej 21, 5330 Munkebo, Denmark | K13: 10.53666 | L13: 55.46811
A14: 13 | B14: Wind World | C14: 325 | D14: =C14/Overview!$L$2 -> 0.011967449 | H14: Nacelles | I14: DK | J14: Smed Sorensens Vej 5, 6950 Ringkobing, Denmark | K14: 8.23755 | L14: 56.08738
A15: 14 | B15: Tacke | C15: 264 | D15: =C15/Overview!$L$2 -> 0.0097212505 | H15: Generator | I15: DE | J15: Henry-Koch-Str. 9-13, 23570 Travemünde, Germany | K15: 10.843096 | L15: 53.932257
A16: 15 | B16: Dewind | C16: 218 | D16: =C16/Overview!$L$2 -> 0.0080273963 | H16: Blades | I16: IT | J16: Via Ludovico Ariosto, 12, 74100 Taranto, Italy | K16: 17.375305 | L16: 40.453884
A17: 16 | B17: Siemens-Gamesa | C17: 184 | D17: =C17/Overview!$L$2 -> 0.006775417 | H17: Blades | I17: ES | J17: Avda de los Vientos, num. 22, 13520, Daimiel, Spain | K17: -3.61498 | L17: 39.07004
A18: 17 | B18: Fuhrländer | C18: 182 | D18: =C18/Overview!$L$2 -> 0.0067017712 | H18: Blades | I18: GB | J18: West Medina Mills, Stag Lane, Newport, PO30 5TR Isle of Wight, United Kingdom | K18: -1.300546 | L18: 50.722619
A19: 18 | B19: Südwind | C19: 128 | D19: =C19/Overview!$L$2 -> 0.0047133336 | G19: NORDEX | I19: DE | J19: Handelsstrasse 3, 18069 Rostock, Germany | K19: 12.077835 | L19: 54.124888
A20: 19 | B20: Ecotecnia | C20: 128 | D20: =C20/Overview!$L$2 -> 0.0047133336 | G20: Neg Micon | J20: Merged with VESTAS in 2004
A21: 20 | B21: Made | C21: 95 | D21: =C21/Overview!$L$2 -> 0.0034981773 | E21: =SUM(D2:D21) -> 0.85440218 | G21: Senvion | J21: Sold to Siemes Gamesa in October 2019
B22: #ND | C22: 2782 | E22: =C22/Overview!$L$2 -> 0.10244136 | G22: Bonus | J22: Aquired by Siemens Wind Power in 2004
G23: Siemens Gamesa | H23: Trainingscenter | I23: AT | J23: Siemensstraße 90, 1210 Vienna, Austria | K23: 16.422584 | L23: 48.269044
H24: Non-operational | I24: BE | J24: Guido Gezellestraat 125 Vlaams-Brabant 1654 Beersel, 1654 Huizingen, Belgium
B25: No specific production location provided, thus assumptions are made | H25: Non-operational | I25: HR | J25: Heinzelova 70 A, 10000 Zagreb, Croatia
B26: Does not exist anymore | H26: Blades? | I26: DK | J26: Assensvej 11, 9220 Aalborg, Denmark
H27: Generators/Towers? | I27: DK | J27: Borupvej 16, 7330 Brande, Denmark
H28: Non-operational | I28: DK | J28: Fiskergade 1, 7100 Vejle, Denmark
H29: Non-operational | I29: FI | J29: Tarvonsalmenkatu 19 FI-02600, Espoo, Finnland
H30: Non-operational | I30: FR | J30: 97 allée Alexandre Borodine – Cedre 3 69800 Saint Priest, Lyon, France
H31: Non-operational | I31: FR | J31: 60 Avenue du Général de Gaulle, 92800 Puteaux, France
H32: Non-operational | I32: DE | J32: Seewindstraße 4, 27572 Bremerhaven, Germany
H33: Non-operational | I33: DE | J33: Mary-Sommerville-Straße 14, 28359 Bremen, Germany
H34: Generators/Nacelles | I34: DE | J34: An der Baumroenne 4, 27472 Cuxhaven, Germany
H35: Non-operational | I35: DE | J35: Beim Strohhause 17-31, 20097 Hamburg, Germany
H36: Non-operational | I36: DE | J36: Albert-Betz Strasse 1, 24783 Osterroenfeld, Germany
H37: Non-operational | I37: GR | J37: 44 - 46 Riga Fereou str & Messogion Ave Neo Psychiko - Attika Greece 15451, Athens, Greece
H38: Non-operational | I38: HU | J38: Gizella út 51-57, 1143 Budapest, Hungary
... H58: Distribution port offshore | I58: GB | J58: Sir William Siemens Way, Alexandra Dock (West), Hull HU9 1TA, United Kingdom

Sheet Source
A23: Source: | B23: https://www.enercon.de/en/company/production-sourcing
A24: Source: | B24: https://www.vestas.com/en/about/our-locations/production

Sheet ENERCON
A1: Component | B1: Sub-component | C1: ISO_A2 | D1: Address | E1: lon | F1: lat
A2: Rotor | B2: Blades | C2: PT | D2: Av. de Cabo Verde 36, Viana do Castelo, Portugal | E2: -8.84806 | F2: 41.6929
A3: Rotor | B3: Blades | C3: TR | D3: 10042 Sokak No 12 İAOSB, 35680 Çiğli/İzmir, Türkiye | E3: 27.031804 | F3: 38.474006
A4: Rotor | B4: Hub | C4: DE | D4: Borsigstraße 15, 26607 Aurich, Germany | E4: 7.49775 | F4: 53.50891
A5: Nacelle | B5: Generator | C5: DE | D5: August-Bebel-Damm 26, 39126 Magdeburg, Germany | E5: 11.68085 | F5: 52.20541
A6: Nacelle | B6: Generator | C6: PL | D6: Oświęcimska 102e, 45-641 Opole, Poland | E6: 17.95966 | F6: 50.60241
A7: Nacelle | B7: Generator | C7: PT | D7: Parque Empresarial de Lanheses, Lanheses, Portugal | E7: -8.6256 | F7: 41.9989
A8: Nacelle | B8: Nacelle | C8: DE | D8: Borsigstraße 15, 26607 Aurich, Germany | E8: 7.49775 | F8: 53.50891
A9: Tower | B9: Tower | C9: DE | D9: Borsigstraße 15, 26607 Aurich, Germany | E9: 7.49775 | F9: 53.50891

Sheet VESTAS
A1: Component | B1: Sub-component | C1: ISO_A2 | D1: Address | E1: lon | F1: lat
A2: Rotor | B2: Blades | C2: DK | D2: Vingevej 1, 4900 Nakskov, Denmark | E2: 11.12127 | F2: 54.828999
A3: Rotor | B3: Blades | C3: DK | D3: Smed Hansensvej 19, 6940 Lem, Denmark | E3: 8.3829 | F3: 56.021679
A4: Nacelle | B4: Nacelles | C4: DK | D4: E.F. Jacobsensvej 3, 6950 Ringkobing, Denmark | E4: 8.23574 | F4: 56.08888
A5: Nacelle | B5: Nacelles | C5: DK | D5: Lindø Sydvej 21, 5330 Munkebo, Denmark | E5: 10.53666 | F5: 55.46811
A6: Nacelle | B6: Nacelles | C6: DK | D6: Smed Sorensens Vej 5, 6950 Ringkobing, Denmark | E6: 8.23755 | F6: 56.08738
A7: Nacelle | B7: Generator | C7: DE | D7: Henry-Koch-Str. 9-13, 23570 Travemünde, Germany | E7: 10.843096 | F7: 53.932257
A8: Rotor | B8: Blades | C8: IT | D8: Via Ludovico Ariosto, 12, 74100 Taranto, Italy | E8: 17.375305 | F8: 40.453884
A9: Rotor | B9: Blades | C9: ES | D9: Avda de los Vientos, num. 22, 13520, Daimiel, Spain | E9: -3.61498 | F9: 39.07004
A10: Rotor | B10: Blades | C10: GB | D10: West Medina Mills, Stag Lane, Newport, PO30 5TR Isle of Wight, United Kingdom | E10: -1.300546 | F10: 50.722619
A11: Tower | B11: Tower | C11: ES | D11: Parque Empresarial Principado de Asturias, 33400 Avilés, Asturias, Spain | E11: -5.9245 | F11: 43.5547
A12: Tower | B12: Tower | C12: PL | D12: GSG Towers, Marynarki Polskiej 87, 80-557 Gdańsk, Poland | E12: 18.6013 | F12: 54.3853
A13: Tower | B13: Tower | C13: UK | D13: CS Wind UK, Machrihanish Business Park, Campbeltown, PA28 6NU, Scotland, United Kingdom | E13: -5.7026 | F13: 55.4367
A14: Tower | B14: Tower | C14: DK | D14: Welcon, Bøgekildevej 5, 7323 Give, Denmark | E14: 9.2497 | F14: 55.8445
